Workbook

Sheet Missed L4-L1
A1: Level | B1: ID | C1: Doc | D1: Lang | E1: Gold pages | F1: Question | G1: TF-IDF raw | H1: TF-IDF pipeline | I1: BM25 | J1: Dense (BGE-M3) | K1: Hybrid RRF (before reranker) | L1: Reranker (after) | M1: Rank change (before − after) | N1: Status | O1: Reranker top-1 page | P1: Reranker top-1 score
A2: L4 | B2: p300-041 | C2: p300 | D2: en | E2: 188 332 | F2: Compare how attention works in a transformer layer versus in an RNN encoder-decoder. | G2: 27 | H2: 18 | I2: 18 | J2: 6 | K2: 10 | L2: 11 | M2: =K2-L2 -> -1 | N2: =IF(AND(K2<=5,L2<=5),"Only single retrievers miss",IF(AND(K2>5,L2<=5),"Reranker fixed",IF(AND(K2<=5,L2>5),"Reranker broke","Both miss"))) -> Both miss | O2: 293 | P2: 0.7718
A3: L4 | B3: LLMbookzh-042 | C3: LLMbookzh | D3: zh | E3: 183 204 | F3: InstructGPT 采用的 RLHF 与 DPO 在优化策略模型的方式上有什么不同? | G3: 11 | H3: 20 | I3: 19 | J3: 28 | K3: 20 | L3: 10 | M3: =K3-L3 -> 10 | N3: =IF(AND(K3<=5,L3<=5),"Only single retrievers miss",IF(AND(K3>5,L3<=5),"Reranker fixed",IF(AND(K3<=5,L3>5),"Reranker broke","Both miss"))) -> Both miss | O3: 211 | P3: 0.9764
A4: L4 | B4: clrs-041 | C4: clrs | D4: en | E4: 380 406 | F4: Why does a naive recursive solution like RECURSIVE-MATRIX-CHAIN take exponential time, and how does dynamic programming avoid that cost? | G4: 1 | H4: 1 | I4: 17 | J4: 3 | K4: 6 | L4: 6 | M4: =K4-L4 -> 0 | N4: =IF(AND(K4<=5,L4<=5),"Only single retrievers miss",IF(AND(K4>5,L4<=5),"Reranker fixed",IF(AND(K4<=5,L4>5),"Reranker broke","Both miss"))) -> Both miss | O4: 410 | P4: 0.9604
A5: L4 | B5: d2l-zh-041 | C5: d2l-zh | D5: zh | E5: 506 511 519 | F5: Adagrad的学习率衰减过于剧烈,RMSProp和Adam/Yogi分别是如何改进这一问题的? | G5: 9 | H5: 3 | I5: 2 | J5: 5 | K5: 2 | L5: 7 | M5: =K5-L5 -> -5 | N5: =IF(AND(K5<=5,L5<=5),"Only single retrievers miss",IF(AND(K5>5,L5<=5),"Reranker fixed",IF(AND(K5<=5,L5>5),"Reranker broke","Both miss"))) -> Reranker broke | O5: 508 | P5: 0.9824
A6: L4 | B6: LLMbookzh-044 | C6: LLMbookzh | D6: zh | E6: 232 241 | F6: 以 8 比特为例,对称量化与非对称量化的参数设置有何不同?将 LLaMA (7B) 从 FP16 量化到 INT8/INT4 后,显存和性能如何变化? | G6: 2 | H6: 2 | I6: 2 | J6: 6 | K6: 2 | L6: 4 | M6: =K6-L6 -> -2 | N6: =IF(AND(K6<=5,L6<=5),"Only single retrievers miss",IF(AND(K6>5,L6<=5),"Reranker fixed",IF(AND(K6<=5,L6>5),"Reranker broke","Both miss"))) -> Only single retrievers miss | O6: 231 | P6: 0.9776
A7: L4 | B7: d2l-zh-042 | C7: d2l-zh | D7: zh | E7: 438 720 | F7: Transformer的位置编码与BERT的位置嵌入有什么区别? | G7: 31 | H7: 7 | I7: 16 | J7: 2 | K7: 5 | L7: 3 | M7: =K7-L7 -> 2 | N7: =IF(AND(K7<=5,L7<=5),"Only single retrievers miss",IF(AND(K7>5,L7<=5),"Reranker fixed",IF(AND(K7<=5,L7>5),"Reranker broke","Both miss"))) -> Only single retrievers miss | O7: 719 | P7: 0.998
A8: L4 | B8: LLMbookzh-045 | C8: LLMbookzh | D8: zh | E8: 273 281 | F8: 基于大语言模型的规划框架与智能体框架中,'制定方案'和'执行动作'分别由哪些组件负责? | G8: 8 | H8: 13 | I8: 3 | J8: 1 | K8: 2 | L8: 2 | M8: =K8-L8 -> 0 | N8: =IF(AND(K8<=5,L8<=5),"Only single retrievers miss",IF(AND(K8>5,L8<=5),"Reranker fixed",IF(AND(K8<=5,L8>5),"Reranker broke","Both miss"))) -> Only single retrievers miss | O8: 272 | P8: 0.998
A9: L4 | B9: clrs-042 | C9: clrs | D9: en | E9: 58 111 | F9: Compare the recursion tree for merge sort's recurrence T(n) = 2T(n/2) + cn with the one for T(n) = 3T(n/4) + cn^2: branching factor, subproblem size at depth i, and cost per node. | G9: 6 | H9: 10 | I9: 1 | J9: 2 | K9: 2 | L9: 2 | M9: =K9-L9 -> 0 | N9: =IF(AND(K9<=5,L9<=5),"Only single retrievers miss",IF(AND(K9>5,L9<=5),"Reranker fixed",IF(AND(K9<=5,L9>5),"Reranker broke","Both miss"))) -> Only single retrievers miss | O9: 109 | P9: 0.9478
A10: L4 | B10: d2l-zh-044 | C10: d2l-zh | D10: zh | E10: 135 143 | F10: softmax的从零实现和简洁实现在数值计算上有什么不同?为什么简洁实现要这样改? | G10: 12 | H10: 13 | I10: 1 | J10: 2 | K10: 2 | L10: 1 | M10: =K10-L10 -> 1 | N10: =IF(AND(K10<=5,L10<=5),"Only single retrievers miss",IF(AND(K10>5,L10<=5),"Reranker fixed",IF(AND(K10<=5,L10>5),"Reranker broke","Both miss"))) -> Only single retrievers miss | O10: 143 | P10: 0.9579
A11: L3 | B11: clrs-037 | C11: clrs | D11: zh | E11: 715 | F11: Floyd-Warshall 的递归定义中，为什么 d_ij^(0) = w_ij？ | G11: >50 | H11: >50 | I11: 35 | J11: 19 | K11: 16 | L11: 20 | M11: =K11-L11 -> -4 | N11: =IF(AND(K11<=5,L11<=5),"Only single retrievers miss",IF(AND(K11>5,L11<=5),"Reranker fixed",IF(AND(K11<=5,L11>5),"Reranker broke","Both miss"))) -> Both miss | O11: 716 | P11: 0.0969
A12: L3 | B12: p300-036 | C12: p300 | D12: zh | E12: 199 | F12: 一个 transformer block 内部的计算顺序是什么？residual connection 加在哪里？ | G12: 28 | H12: 17 | I12: 24 | J12: 4 | K12: 9 | L12: 5 | M12: =K12-L12 -> 4 | N12: =IF(AND(K12<=5,L12<=5),"Only single retrievers miss",IF(AND(K12>5,L12<=5),"Reranker fixed",IF(AND(K12<=5,L12>5),"Reranker broke","Both miss"))) -> Reranker fixed | O12: 192 | P12: 0.8824
A13: L3 | B13: clrs-035 | C13: clrs | D13: zh | E13: 539 | F13: Fibonacci heap 中 extract-min（抽取最小节点）操作的实际代价 (actual work) 是多少？ | G13: 3 | H13: 8 | I13: 11 | J13: 8 | K13: 6 | L13: 4 | M13: =K13-L13 -> 2 | N13: =IF(AND(K13<=5,L13<=5),"Only single retrievers miss",IF(AND(K13>5,L13<=5),"Reranker fixed",IF(AND(K13<=5,L13>5),"Reranker broke","Both miss"))) -> Reranker fixed | O13: 683 | P13: 0.7379
A14: L3 | B14: LLMbookzh-036 | C14: LLMbookzh | D14: en | E14: 104 | F14: Why does the Transformer need position embeddings? What does self-attention degrade into without them? | G14: >50 | H14: >50 | I14: >50 | J14: 5 | K14: 18 | L14: 2 | M14: =K14-L14 -> 16 | N14: =IF(AND(K14<=5,L14<=5),"Only single retrievers miss",IF(AND(K14>5,L14<=5),"Reranker fixed",IF(AND(K14<=5,L14>5),"Reranker broke","Both miss"))) -> Reranker fixed | O14: 96 | P14: 0.7712
A15: L3 | B15: d2l-zh-036 | C15: d2l-zh | D15: zh | E15: 378 | F15: Which probabilistic graphical model does the book use to motivate 双向循环神经网络 (bidirectional RNNs)? | G15: >50 | H15: >50 | I15: 49 | J15: 7 | K15: 11 | L15: 2 | M15: =K15-L15 -> 9 | N15: =IF(AND(K15<=5,L15<=5),"Only single retrievers miss",IF(AND(K15>5,L15<=5),"Reranker fixed",IF(AND(K15<=5,L15>5),"Reranker broke","Both miss"))) -> Reranker fixed | O15: 380 | P15: 0.8102
A16: L3 | B16: d2l-zh-038 | C16: d2l-zh | D16: zh | E16: 655 | F16: What are the three stages of a fully convolutional network (全卷积网络) for semantic segmentation, and how is its transposed convolution initialized? | G16: >50 | H16: >50 | I16: >50 | J16: 2 | K16: 7 | L16: 2 | M16: =K16-L16 -> 5 | N16: =IF(AND(K16<=5,L16<=5),"Only single retrievers miss",IF(AND(K16>5,L16<=5),"Reranker fixed",IF(AND(K16<=5,L16>5),"Reranker broke","Both miss"))) -> Reranker fixed | O16: 649 | P16: 0.7049
A17: L3 | B17: d2l-zh-039 | C17: d2l-zh | D17: en | E17: 199 | F17: Why is accuracy rarely the right metric once an ML system is used for automated decisions? | G17: >50 | H17: >50 | I17: >50 | J17: 4 | K17: 10 | L17: 1 | M17: =K17-L17 -> 9 | N17: =IF(AND(K17<=5,L17<=5),"Only single retrievers miss",IF(AND(K17>5,L17<=5),"Reranker fixed",IF(AND(K17<=5,L17>5),"Reranker broke","Both miss"))) -> Reranker fixed | O17: 199 | P17: 0.8649
A18: L3 | B18: LLMbookzh-034 | C18: LLMbookzh | D18: en | E18: 30 | F18: According to Ilya Sutskever, what is large-scale pre-training essentially doing? | G18: >50 | H18: 32 | I18: >50 | J18: 2 | K18: 8 | L18: 1 | M18: =K18-L18 -> 7 | N18: =IF(AND(K18<=5,L18<=5),"Only single retrievers miss",IF(AND(K18>5,L18<=5),"Reranker fixed",IF(AND(K18<=5,L18>5),"Reranker broke","Both miss"))) -> Reranker fixed | O18: 30 | P18: 0.9564
A19: L3 | B19: LLMbookzh-039 | C19: LLMbookzh | D19: en | E19: 295 | F19: How is a model's expected win rate calculated in the Elo rating system used for pairwise LLM comparison? | G19: >50 | H19: >50 | I19: >50 | J19: 1 | K19: 6 | L19: 1 | M19: =K19-L19 -> 5 | N19: =IF(AND(K19<=5,L19<=5),"Only single retrievers miss",IF(AND(K19>5,L19<=5),"Reranker fixed",IF(AND(K19<=5,L19>5),"Reranker broke","Both miss"))) -> Reranker fixed | O19: 295 | P19: 0.9654
A20: L3 | B20: p300-037 | C20: p300 | D20: zh | E20: 312 | F20: 简单 RNN 中 hidden state h_t 是怎么计算的？参数矩阵 W、U、V 的维度分别是多少？ | G20: 37 | H20: 27 | I20: 6 | J20: 1 | K20: 6 | L20: 1 | M20: =K20-L20 -> 5 | N20: =IF(AND(K20<=5,L20<=5),"Only single retrievers miss",IF(AND(K20>5,L20<=5),"Reranker fixed",IF(AND(K20<=5,L20>5),"Reranker broke","Both miss"))) -> Reranker fixed | O20: 312 | P20: 0.9701
A21: L3 | B21: d2l-zh-037 | C21: d2l-zh | D21: en | E21: 424 | F21: When should additive attention be used instead of scaled dot-product attention? | G21: 1 | H21: 1 | I21: 7 | J21: 3 | K21: 2 | L21: 2 | M21: =K21-L21 -> 0 | N21: =IF(AND(K21<=5,L21<=5),"Only single retrievers miss",IF(AND(K21>5,L21<=5),"Reranker fixed",IF(AND(K21<=5,L21>5),"Reranker broke","Both miss"))) -> Only single retrievers miss | O21: 423 | P21: 0.565
A22: L3 | B22: clrs-040 | C22: clrs | D22: zh | E22: 1080 | F22: 在 formal language 的框架下，复杂度类 P 是如何定义的？ | G22: 16 | H22: 16 | I22: 13 | J22: 1 | K22: 2 | L22: 2 | M22: =K22-L22 -> 0 | N22: =IF(AND(K22<=5,L22<=5),"Only single retrievers miss",IF(AND(K22>5,L22<=5),"Reranker fixed",IF(AND(K22<=5,L22>5),"Reranker broke","Both miss"))) -> Only single retrievers miss | O22: 1074 | P22: 0.974
A23: L3 | B23: clrs-036 | C23: clrs | D23: zh | E23: 668 | F23: 单源最短路径中，每个顶点的 predecessor 属性 v.π 有什么作用？最短路径最多包含多少条边？ | G23: >50 | H23: >50 | I23: 15 | J23: 1 | K23: 4 | L23: 1 | M23: =K23-L23 -> 3 | N23: =IF(AND(K23<=5,L23<=5),"Only single retrievers miss",IF(AND(K23>5,L23<=5),"Reranker fixed",IF(AND(K23<=5,L23>5),"Reranker broke","Both miss"))) -> Only single retrievers miss | O23: 668 | P23: 0.957
A24: L3 | B24: d2l-zh-034 | C24: d2l-zh | D24: en | E24: 706 | F24: In the GloVe co-occurrence table, why is P(solid|ice)/P(solid|steam) large (≈8.9) while the ratio for 'water' is close to 1? | G24: 16 | H24: 3 | I24: 1 | J24: 1 | K24: 1 | L24: 1 | M24: =K24-L24 -> 0 | N24: =IF(AND(K24<=5,L24<=5),"Only single retrievers miss",IF(AND(K24>5,L24<=5),"Reranker fixed",IF(AND(K24<=5,L24>5),"Reranker broke","Both miss"))) -> Only single retrievers miss | O24: 706 | P24: 0.9642
A25: L3 | B25: LLMbookzh-037 | C25: LLMbookzh | D25: en | E25: 193 | F25: In PPO, why is the probability ratio r_t(θ) clipped to [1−ε, 1+ε]? | G25: 7 | H25: 2 | I25: 1 | J25: 1 | K25: 1 | L25: 1 | M25: =K25-L25 -> 0 | N25: =IF(AND(K25<=5,L25<=5),"Only single retrievers miss",IF(AND(K25>5,L25<=5),"Reranker fixed",IF(AND(K25<=5,L25>5),"Reranker broke","Both miss"))) -> Only single retrievers miss | O25: 193 | P25: 0.9647
A26: L3 | B26: LLMbookzh-038 | C26: LLMbookzh | D26: zh | E26: 258 | F26: In in-context learning, 示例设计 (demonstration design) 有哪三个关键因素? | G26: 25 | H26: 4 | I26: 5 | J26: 2 | K26: 1 | L26: 1 | M26: =K26-L26 -> 0 | N26: =IF(AND(K26<=5,L26<=5),"Only single retrievers miss",IF(AND(K26>5,L26<=5),"Reranker fixed",IF(AND(K26<=5,L26>5),"Reranker broke","Both miss"))) -> Only single retrievers miss | O26: 258 | P26: 0.9834
A27: L3 | B27: LLMbookzh-040 | C27: LLMbookzh | D27: en | E27: 308 | F27: What did SQuAD 2.0 add compared with the original SQuAD, and what is SQuAD's main evaluation metric? | G27: 1 | H27: 1 | I27: 6 | J27: 1 | K27: 1 | L27: 1 | M27: =K27-L27 -> 0 | N27: =IF(AND(K27<=5,L27<=5),"Only single retrievers miss",IF(AND(K27>5,L27<=5),"Reranker fixed",IF(AND(K27<=5,L27>5),"Reranker broke","Both miss"))) -> Only single retrievers miss | O27: 308 | P27: 0.9689
A28: L3 | B28: p300-039 | C28: p300 | D28: zh | E28: 459 | F28: 依存句法结构 (dependency structure) 用什么样的图来表示？V 和 A 分别代表什么？ | G28: 6 | H28: 7 | I28: 1 | J28: 1 | K28: 1 | L28: 1 | M28: =K28-L28 -> 0 | N28: =IF(AND(K28<=5,L28<=5),"Only single retrievers miss",IF(AND(K28>5,L28<=5),"Reranker fixed",IF(AND(K28<=5,L28>5),"Reranker broke","Both miss"))) -> Only single retrievers miss | O28: 459 | P28: 0.9752
A29: L3 | B29: clrs-033 | C29: clrs | D29: zh | E29: 339 | F29: RB-INSERT-FIXUP 的 while 循环所维护的 loop invariant 中，红黑树最多会违反哪几条 red-black properties？ | G29: 6 | H29: 4 | I29: 3 | J29: 1 | K29: 1 | L29: 1 | M29: =K29-L29 -> 0 | N29: =IF(AND(K29<=5,L29<=5),"Only single retrievers miss",IF(AND(K29>5,L29<=5),"Reranker fixed",IF(AND(K29<=5,L29>5),"Reranker broke","Both miss"))) -> Only single retrievers miss | O29: 339 | P29: 0.9891
A30: L2 | B30: clrs-018 | C30: clrs | D30: en | E30: 49 | F30: When inserting a new element into the already-sorted prefix, how far does insertion sort typically have to look, and what does that mean for its typical running time? | G30: >50 | H30: >50 | I30: >50 | J30: 4 | K30: 23 | L30: 8 | M30: =K30-L30 -> 15 | N30: =IF(AND(K30<=5,L30<=5),"Only single retrievers miss",IF(AND(K30>5,L30<=5),"Reranker fixed",IF(AND(K30<=5,L30>5),"Reranker broke","Both miss"))) -> Both miss | O30: 45 | P30: 0.6336
A31: L2 | B31: clrs-023 | C31: clrs | D31: en | E31: 398 | F31: How much time and memory does the bottom-up procedure for choosing the best order of matrix multiplications need, and why? | G31: 28 | H31: >50 | I31: 4 | J31: 3 | K31: 1 | L31: 7 | M31: =K31-L31 -> -6 | N31: =IF(AND(K31<=5,L31<=5),"Only single retrievers miss",IF(AND(K31>5,L31<=5),"Reranker fixed",IF(AND(K31<=5,L31>5),"Reranker broke","Both miss"))) -> Reranker broke | O31: 410 | P31: 0.3469
A32: L2 | B32: d2l-zh-033 | C32: d2l-zh | D32: zh | E32: 242 | F32: 在GPU上训练时,为什么每个小批量都把损失打印到命令行会拖慢训练? | G32: 3 | H32: 2 | I32: 12 | J32: 25 | K32: 11 | L32: 3 | M32: =K32-L32 -> 8 | N32: =IF(AND(K32<=5,L32<=5),"Only single retrievers miss",IF(AND(K32>5,L32<=5),"Reranker fixed",IF(AND(K32<=5,L32>5),"Reranker broke","Both miss"))) -> Reranker fixed | O32: 560 | P32: 0.8016
A33: L2 | B33: clrs-030 | C33: clrs | D33: en | E33: 870 | F33: Algebraically, how does the simplex method move from one corner of the feasible region to another? | G33: 9 | H33: 4 | I33: 4 | J33: 18 | K33: 7 | L33: 3 | M33: =K33-L33 -> 4 | N33: =IF(AND(K33<=5,L33<=5),"Only single retrievers miss",IF(AND(K33>5,L33<=5),"Reranker fixed",IF(AND(K33<=5,L33>5),"Reranker broke","Both miss"))) -> Reranker fixed | O33: 869 | P33: 0.9411
A34: L2 | B34: d2l-zh-026 | C34: d2l-zh | D34: zh | E34: 469 | F34: 梯度下降时学习率设得太大或太小,分别会出现什么现象? | G34: 11 | H34: 13 | I34: 33 | J34: 2 | K34: 7 | L34: 2 | M34: =K34-L34 -> 5 | N34: =IF(AND(K34<=5,L34<=5),"Only single retrievers miss",IF(AND(K34>5,L34<=5),"Reranker fixed",IF(AND(K34<=5,L34>5),"Reranker broke","Both miss"))) -> Reranker fixed | O34: 483 | P34: 0.9557
A35: L2 | B35: d2l-zh-031 | C35: d2l-zh | D35: zh | E35: 683 | F35: 为什么word2vec、GloVe这类预训练词向量无法区分“bank”在不同句子中的含义? | G35: 2 | H35: 7 | I35: 1 | J35: 17 | K35: 9 | L35: 1 | M35: =K35-L35 -> 8 | N35: =IF(AND(K35<=5,L35<=5),"Only single retrievers miss",IF(AND(K35>5,L35<=5),"Reranker fixed",IF(AND(K35<=5,L35>5),"Reranker broke","Both miss"))) -> Reranker fixed | O35: 683 | P35: 0.9149
A36: L2 | B36: p300-023 | C36: p300 | D36: en | E36: 139 | F36: How could you work out what an unfamiliar vegetable name means just from the sentences it appears in? | G36: >50 | H36: >50 | I36: >50 | J36: 1 | K36: 8 | L36: 1 | M36: =K36-L36 -> 7 | N36: =IF(AND(K36<=5,L36<=5),"Only single retrievers miss",IF(AND(K36>5,L36<=5),"Reranker fixed",IF(AND(K36<=5,L36>5),"Reranker broke","Both miss"))) -> Reranker fixed | O36: 139 | P36: 0.011
A37: L2 | B37: p300-031 | C37: p300 | D37: en | E37: 414 | F37: Why is finding and labeling names of people and places harder than tagging each word with its part of speech? | G37: 22 | H37: >50 | I37: 26 | J37: 1 | K37: 8 | L37: 1 | M37: =K37-L37 -> 7 | N37: =IF(AND(K37<=5,L37<=5),"Only single retrievers miss",IF(AND(K37>5,L37<=5),"Reranker fixed",IF(AND(K37<=5,L37>5),"Reranker broke","Both miss"))) -> Reranker fixed | O37: 414 | P37: 0.9775
A38: L2 | B38: d2l-zh-019 | C38: d2l-zh | D38: zh | E38: 218 | F38: 如果某一层需要一个在训练过程中始终不被更新的权重,在MXNet中应该怎么实现? | G38: 15 | H38: >50 | I38: 7 | J38: 1 | K38: 4 | L38: 2 | M38: =K38-L38 -> 2 | N38: =IF(AND(K38<=5,L38<=5),"Only single retrievers miss",IF(AND(K38>5,L38<=5),"Reranker fixed",IF(AND(K38<=5,L38>5),"Reranker broke","Both miss"))) -> Only single retrievers miss | O38: 225 | P38: 0.635
A39: L2 | B39: p300-019 | C39: p300 | D39: en | E39: 68 | F39: What is the most helpful way to picture the operations needed to turn 'intention' into 'execution'? | G39: 1 | H39: 1 | I39: 1 | J39: 7 | K39: 3 | L39: 2 | M39: =K39-L39 -> 1 | N39: =IF(AND(K39<=5,L39<=5),"Only single retrievers miss",IF(AND(K39>5,L39<=5),"Reranker fixed",IF(AND(K39<=5,L39>5),"Reranker broke","Both miss"))) -> Only single retrievers miss | O39: 69 | P39: 0.5315
A40: L2 | B40: d2l-zh-023 | C40: d2l-zh | D40: zh | E40: 294 | F40: “批量规范化”这个名字是怎么来的? | G40: 6 | H40: 6 | I40: 8 | J40: 2 | K40: 5 | L40: 1 | M40: =K40-L40 -> 4 | N40: =IF(AND(K40<=5,L40<=5),"Only single retrievers miss",IF(AND(K40>5,L40<=5),"Reranker fixed",IF(AND(K40<=5,L40>5),"Reranker broke","Both miss"))) -> Only single retrievers miss | O40: 294 | P40: 0.9846
...

Sheet Summary
A1: Status | B1: L4 | C1: L3 | D1: L2 | E1: L1 | F1: Total
A2: Both miss | B2: =COUNTIFS('Missed L4-L1'!$A$2:$A$60,"L4",'Missed L4-L1'!$N$2:$N$60,$A2) -> 3 | C2: =COUNTIFS('Missed L4-L1'!$A$2:$A$60,"L3",'Missed L4-L1'!$N$2:$N$60,$A2) -> 1 | D2: =COUNTIFS('Missed L4-L1'!$A$2:$A$60,"L2",'Missed L4-L1'!$N$2:$N$60,$A2) -> 1 | E2: =COUNTIFS('Missed L4-L1'!$A$2:$A$60,"L1",'Missed L4-L1'!$N$2:$N$60,$A2) -> 0 | F2: =SUM(B2:E2) -> 5
A3: Reranker broke | B3: =COUNTIFS('Missed L4-L1'!$A$2:$A$60,"L4",'Missed L4-L1'!$N$2:$N$60,$A3) -> 1 | C3: =COUNTIFS('Missed L4-L1'!$A$2:$A$60,"L3",'Missed L4-L1'!$N$2:$N$60,$A3) -> 0 | D3: =COUNTIFS('Missed L4-L1'!$A$2:$A$60,"L2",'Missed L4-L1'!$N$2:$N$60,$A3) -> 1 | E3: =COUNTIFS('Missed L4-L1'!$A$2:$A$60,"L1",'Missed L4-L1'!$N$2:$N$60,$A3) -> 0 | F3: =SUM(B3:E3) -> 2
A4: Reranker fixed | B4: =COUNTIFS('Missed L4-L1'!$A$2:$A$60,"L4",'Missed L4-L1'!$N$2:$N$60,$A4) -> 0 | C4: =COUNTIFS('Missed L4-L1'!$A$2:$A$60,"L3",'Missed L4-L1'!$N$2:$N$60,$A4) -> 9 | D4: =COUNTIFS('Missed L4-L1'!$A$2:$A$60,"L2",'Missed L4-L1'!$N$2:$N$60,$A4) -> 6 | E4: =COUNTIFS('Missed L4-L1'!$A$2:$A$60,"L1",'Missed L4-L1'!$N$2:$N$60,$A4) -> 1 | F4: =SUM(B4:E4) -> 16
A5: Only single retrievers miss | B5: =COUNTIFS('Missed L4-L1'!$A$2:$A$60,"L4",'Missed L4-L1'!$N$2:$N$60,$A5) -> 5 | C5: =COUNTIFS('Missed L4-L1'!$A$2:$A$60,"L3",'Missed L4-L1'!$N$2:$N$60,$A5) -> 9 | D5: =COUNTIFS('Missed L4-L1'!$A$2:$A$60,"L2",'Missed L4-L1'!$N$2:$N$60,$A5) -> 15 | E5: =COUNTIFS('Missed L4-L1'!$A$2:$A$60,"L1",'Missed L4-L1'!$N$2:$N$60,$A5) -> 7 | F5: =SUM(B5:E5) -> 36
A6: Total | B6: =SUM(B2:B5) -> 9 | C6: =SUM(C2:C5) -> 19 | D6: =SUM(D2:D5) -> 23 | E6: =SUM(E2:E5) -> 8 | F6: =SUM(F2:F5) -> 59
A8: Both miss = gold outside top 5 before and after reranker. Reranker broke = top 5 before, out after. Reranker fixed = out before, top 5 after. Only single retrievers miss = hybrid and reranker both find it; some single retriever (TF-IDF/BM25/Dense) missed.
